<?xml version='1.0'?>

<robot name="slam_bot" xmlns:xacro="http://www.ros.org/wiki/xacro">
<xacro:include filename="$(find RoboND-SLAM-Project)/urdf/slam_bot.gazebo" />
  <link name="robot_footprint"></link>

  <joint name="robot_footprint_joint" type="fixed">
    <origin xyz="0 0 0" rpy="0 0 0" />
    <parent link="robot_footprint"/>
    <child link="chassis" />
  </joint>


  <link name='chassis'>
    <pose>0 0 0.1 0 0 0</pose>

    <inertial>
      <mass value="15.0"/>
      <origin xyz="0.0 0 0" rpy=" 0 0 0"/>
      <inertia ixx="0.1" ixy="0" ixz="0" iyy="0.1" iyz="0" izz="0.1" />
    </inertial>

    <collision name='collision'>
      <origin xyz="0 0 0" rpy=" 0 0 0"/> 
      <geometry>
        <box size=".4 .2 .05"/>
      </geometry>
    </collision>

    <visual>
      <origin xyz="0 0 0" rpy=" 0 0 0"/>
      <geometry>
        <box size=".4 .2 .05"/>
      </geometry>
    </visual>

  </link>


  <link name='FlatBed'>

    <inertial>
      <mass value="5.0"/>
      <origin xyz="0.0 0 0" rpy=" 0 0 0"/>
      <inertia ixx="0.1" ixy="0" ixz="0" iyy="0.1" iyz="0" izz="0.1"/>
    </inertial>

    <collision name='FlatBed_collision'>
      <origin xyz="0 0 0" rpy=" 0 0 0"/> 
      <geometry>
        <box size=".5 .3 .01"/>
      </geometry>
    </collision>

    <visual>
      <origin xyz="0 0 0" rpy=" 0 0 0"/>
      <geometry>
        <box size=".5 .3 .01"/>
      </geometry>
    </visual>

  </link>

  <joint type="fixed" name="flatbed_joint">
    <origin xyz="0 0 0.022" rpy="0 0 0"/>
    <child link="FlatBed"/>
    <parent link="chassis"/>
  </joint> 


  <link name='Left_front_wheel'>

    <inertial>
      <mass value="5.0"/>
      <origin xyz="0 0 0" rpy="0 0 0"/>
      <inertia ixx="0.1" ixy="0" ixz="0" iyy="0.1" iyz="0" izz="0.1"/>
    </inertial>

    <collision name='collision'>
      <origin xyz="0 0 0" rpy="0 1.5707 1.5707"/> 
      <geometry>
        <cylinder length="0.05" radius="0.05"/>
      </geometry>
    </collision>

    <visual>
      <origin xyz="0 0 0" rpy="0 1.5707 1.5707"/>
      <geometry>
        <cylinder length="0.05" radius="0.05"/>
      </geometry>
    </visual>

  </link>

  <joint type="continuous" name="left_front_wheel_hinge">
    <origin xyz="0.15 0.15 -0.04" rpy="0 0 0"/>
    <child link="Left_front_wheel"/>
    <parent link="chassis"/>
    <axis xyz="0 1 0" rpy="0 0 0"/>
    <limit effort="10000" velocity="1000"/>
    <joint_properties damping="1.0" friction="0.02"/>
  </joint>

 
  <link name='Left_back_wheel'>

    <inertial>
      <mass value="5.0"/>
      <origin xyz="0 0 0" rpy="0 0 0"/>
      <inertia ixx="0.1" ixy="0" ixz="0" iyy="0.1" iyz="0" izz="0.1"/>
    </inertial>

    <collision name='collision'>
      <origin xyz="0 0 0" rpy="0 1.5707 1.5707"/> 
      <geometry>
        <cylinder length="0.05" radius="0.05"/>
      </geometry>
    </collision>

    <visual>
      <origin xyz="0 0 0" rpy="0 1.5707 1.5707"/>
      <geometry>
        <cylinder length="0.05" radius="0.05"/>
      </geometry>
    </visual>
  
  </link>

  <joint type="continuous" name="left_back_wheel_hinge">
    <origin xyz="-0.15 0.15 -0.04" rpy="0 0 0"/>
    <child link="Left_back_wheel"/>
    <parent link="chassis"/>
    <axis xyz="0 1 0" rpy="0 0 0"/>
    <limit effort="10000" velocity="1000"/>
    <joint_properties damping="1.0" friction="0.02"/>
  </joint>


  <link name='Right_front_wheel'>

    <inertial>
      <mass value="5.0"/>
      <origin xyz="0 0 0" rpy="0 0 0"/>
      <inertia ixx="0.1" ixy="0" ixz="0" iyy="0.1" iyz="0" izz="0.1"/>
    </inertial>

    <collision name='collision'>
      <origin xyz="0 0 0" rpy=" 0 1.5707 1.5707"/> 
      <geometry>
        <cylinder length="0.05" radius="0.05"/>
      </geometry>
    </collision>

    <visual>
      <origin xyz="0 0 0" rpy=" 0 1.5707 1.5707"/>
      <geometry>
        <cylinder length="0.05" radius="0.05"/>
      </geometry>
    </visual>

  </link>

  <joint type="continuous" name="right_front_wheel_hinge">
    <origin xyz="0.15 -0.15 -0.04" rpy="0 0 0"/>
    <child link="Right_front_wheel"/>
    <parent link="chassis"/>
    <axis xyz="0 1 0" rpy="0 0 0"/>
    <limit effort="10000" velocity="1000"/>
    <joint_properties damping="1.0" friction="0.02"/>
  </joint>


  <link name='Right_back_wheel'>

    <inertial>
      <mass value="5.0"/>
      <origin xyz="0 0 0" rpy="0 0 0"/>
      <inertia ixx="0.1" ixy="0" ixz="0" iyy="0.1" iyz="0" izz="0.1"/>
    </inertial>

    <collision name='collision'>
      <origin xyz="0 0 0" rpy=" 0 1.5707 1.5707"/> 
      <geometry>
        <cylinder length="0.05" radius="0.05"/>
      </geometry>
    </collision>

    <visual> 
      <origin xyz="0 0 0" rpy=" 0 1.5707 1.5707"/>
      <geometry>
        <cylinder length="0.05" radius="0.05"/>
      </geometry>
    </visual>

  </link>

  <joint type="continuous" name="right_back_wheel_hinge">
    <origin xyz="-0.15 -0.15 -0.04" rpy="0 0 0"/>
    <child link="Right_back_wheel"/>
    <parent link="chassis"/>
    <axis xyz="0 1 0" rpy="0 0 0"/>
    <limit effort="10000" velocity="1000"/>
    <joint_properties damping="1.0" friction="0.02"/>
  </joint>


  <link name='camera'>

    <inertial>
      <mass value="0.1"/>
      <origin xyz="0 0 0" rpy="0 0 0"/>
      <inertia ixx="1e-6" ixy="0" ixz="0" iyy="1e-6" iyz="0" izz="1e-6"/>
    </inertial>

    <collision name='collision'>
      <origin xyz="0 0 0" rpy=" 0 0 0"/> 
      <geometry>
        <box size=".05 .05 .04"/>
      </geometry>
    </collision>

    <visual name='camera_visual'>
      <origin xyz="0 0 0" rpy=" 0 0 0"/>
      <geometry>
      	<mesh filename="package://RoboND-SLAM-Project/meshes/kinect.dae"/>
        <!-- <box size=".04 .05 .04"/> -->
      </geometry>
    </visual>
  
  </link>

  <joint type="fixed" name="camera_joint">
    <origin xyz="0.25 0 -0.005" rpy="0 0 0"/>
    <child link="camera"/>
    <parent link="chassis"/>
  </joint>

  <link name="camera_rgbd_frame"> </link>

  <joint name="camera_rgbd_joint" type="fixed">
    <!-- these values have to be these values otherwise the gazebo camera
        image won't be aligned properly with the frame it is supposedly
        originating from -->
    <origin xyz="0 0 0" rpy="${-pi/2} 0 ${-pi/2}"/>
    <child link="camera_rgbd_frame"/>
    <parent link="camera"/>
  </joint>




  <link name='hokuyo'>

    <inertial>
      <mass value="0.1"/>
      <origin xyz="0.0 0 0" rpy="0 0 0"/>
      <inertia ixx="1e-6" ixy="0" ixz="0" iyy="1e-6" iyz="0" izz="1e-6"/>
    </inertial>

    <collision name='collision'>
      <origin xyz="0 0 0" rpy=" 0 0 0"/> 
      <geometry>
        <box size="0.1 0.1 0.1"/>
      </geometry>
    </collision>

    <visual name='laser_visual'>
      <origin xyz="0 0 0" rpy=" 0 0 0"/>
      <geometry>
        <mesh filename="package://RoboND-SLAM-Project/meshes/hokuyo.dae"/>
      </geometry>
    </visual>
  
  </link>

  <joint type="fixed" name="hokuyo_joint">
    <origin xyz="0.22 0 0.05" rpy="0 0 0"/>
    <child link="hokuyo"/>
    <parent link="chassis"/>
  </joint> 


</robot>
